<?xml version="1.0" encoding="UTF-8"?>
<robot
	name="ardop_description_02">
	<link
		name="base_link">
		<inertial>
			<origin
				xyz="-0.05669211 -0.00059544 0.13127776"
				rpy="0 0 0" />
			<mass
				value="6" />
			<inertia
				ixx="0.000324"
				ixy="0.000000"
				ixz="-0.000054"
				iyy="0.000398"
				iyz="-0.018212"
				izz="0.000293" />
		</inertial>
		<visual>
			<origin
				xyz="0 0 0"
				rpy="0 0 0" />
			<geometry>
				<mesh
					filename="package://ardop_description_02/meshes/base_link.STL" />
			</geometry>
			<material
				name="cream">
				<color
					rgba="0.93 0.94 0.95 1" />
			</material>
		</visual>
		<collision>
			<origin
				xyz="0 0 0"
				rpy="0 0 0" />
			<geometry>
				<mesh
					filename="package://ardop_description_02/meshes/base_link.STL" />
			</geometry>
		</collision>
	</link>

	<link
		name="wheel_front_left_link">
		<inertial>
			<origin
				xyz="0 0.02096815 0"
				rpy="0 0 0" />
			<mass
				value="0.4" />
			<inertia
				ixx="0"
				ixy="0"
				ixz="0"
				iyy="0"
				iyz="0"
				izz="0" />
		</inertial>
		<visual>
			<origin
				xyz="0 0 0"
				rpy="0 0 0" />
			<geometry>
				<mesh
					filename="package://ardop_description_02/meshes/wheel_front_left_link.STL" />
			</geometry>
			<material
				name="dark_blue">
				<color
					rgba="0.17 0.24 0.31 1" />
			</material>
		</visual>
		<collision>
			<origin
				xyz="0 0 0"
				rpy="0 0 0" />
			<geometry>
				<mesh
					filename="package://ardop_description_02/meshes/wheel_front_left_link.STL" />
			</geometry>
		</collision>
	</link>

	<joint
		name="wheel_front_left_joint"
		type="continuous">
		<origin
			xyz="0.03 0.1895 0.05"
			rpy="0 0 0" />
		<parent
			link="base_link" />
		<child
			link="wheel_front_left_link" />
		<axis
			xyz="0 1 0" />
		<limit
			effort="100"
			velocity="100" />
		<safety_controller
			k_velocity="10" />
	</joint>

	<link
		name="wheel_front_right_link">
		<inertial>
			<origin
				xyz="0 -0.02096815 0"
				rpy="0 0 0" />
			<mass
				value="0.4" />
			<inertia
				ixx="0"
				ixy="0"
				ixz="0"
				iyy="0"
				iyz="0"
				izz="0" />
		</inertial>
		<visual>
			<origin
				xyz="0 0 0"
				rpy="0 0 0" />
			<geometry>
				<mesh
					filename="package://ardop_description_02/meshes/wheel_front_right_link.STL" />
			</geometry>
			<material
				name="dark_blue">
				<color
					rgba="0.17 0.24 0.31 1" />
			</material>
		</visual>
		<collision>
			<origin
				xyz="0 0 0"
				rpy="0 0 0" />
			<geometry>
				<mesh
					filename="package://ardop_description_02/meshes/wheel_front_right_link.STL" />
			</geometry>
		</collision>
	</link>

	<joint
		name="wheel_front_right_joint"
		type="continuous">
		<origin
			xyz="0.03 -0.1895 0.05"
			rpy="0 0 0" />
		<parent
			link="base_link" />
		<child
			link="wheel_front_right_link" />
		<axis
			xyz="0 1 0" />
		<limit
			effort="100"
			velocity="100" />
		<safety_controller
			k_velocity="10" />
	</joint>

	<link
		name="wheel_back_left_link">
		<inertial>
			<origin
				xyz="0 0.02096815 0"
				rpy="0 0 0" />
			<mass
				value="0.4" />
			<inertia
				ixx="0"
				ixy="0"
				ixz="0"
				iyy="0"
				iyz="0"
				izz="0" />
		</inertial>
		<visual>
			<origin
				xyz="0 0 0"
				rpy="0 0 0" />
			<geometry>
				<mesh
					filename="package://ardop_description_02/meshes/wheel_back_left_link.STL" />
			</geometry>
			<material
				name="dark_blue">
				<color
					rgba="0.17 0.24 0.31 1" />
			</material>
		</visual>
		<collision>
			<origin
				xyz="0 0 0"
				rpy="0 0 0" />
			<geometry>
				<mesh
					filename="package://ardop_description_02/meshes/wheel_back_left_link.STL" />
			</geometry>
		</collision>
	</link>

	<joint
		name="wheel_back_left_joint"
		type="continuous">
		<origin
			xyz="-0.2 0.1895 0.05"
			rpy="0 0 0" />
		<parent
			link="base_link" />
		<child
			link="wheel_back_left_link" />
		<axis
			xyz="0 1 0" />
		<limit
			effort="100"
			velocity="100" />
		<safety_controller
			k_velocity="10" />
	</joint>

	<link
		name="wheel_back_right_link">
		<inertial>
			<origin
				xyz="0 -0.02096815 0"
				rpy="0 0 0" />
			<mass
				value="0.4" />
			<inertia
				ixx="0"
				ixy="0"
				ixz="0"
				iyy="0"
				iyz="0"
				izz="0" />
		</inertial>
		<visual>
			<origin
				xyz="0 0 0"
				rpy="0 0 0" />
			<geometry>
				<mesh
					filename="package://ardop_description_02/meshes/wheel_back_right_link.STL" />
			</geometry>
			<material
				name="dark_blue">
				<color
					rgba="0.17 0.24 0.31 1" />
			</material>
		</visual>
		<collision>
			<origin
				xyz="0 0 0"
				rpy="0 0 0" />
			<geometry>
				<mesh
					filename="package://ardop_description_02/meshes/wheel_back_right_link.STL" />
			</geometry>
		</collision>
	</link>

	<joint
		name="wheel_back_right_joint"
		type="continuous">
		<origin
			xyz="-0.2 -0.1895 0.05"
			rpy="0 0 0" />
		<parent
			link="base_link" />
		<child
			link="wheel_back_right_link" />
		<axis
			xyz="0 1 0" />
		<limit
			effort="100"
			velocity="100" />
		<safety_controller
			k_velocity="10" />
	</joint>

	<link
		name="shoulder_1_link">
		<inertial>
			<origin
				xyz="0.02786329 -0.03558158 0.00339449" 
				rpy="0 0 0" />
			<mass
				value="0.239718" />
			<inertia
				ixx="0.0"
				ixy="0.0"
				ixz="0.0"
				iyy="0.0"
				iyz="0.0"
				izz="0.0" />
		</inertial>
		<visual>
			<origin
				xyz="0 0 0"
				rpy="0 0 0" />
			<geometry>
				<mesh
					filename="package://ardop_description_02/meshes/shoulder_1_link.STL" />
			</geometry>
			<material
				name="red">
				<color
					rgba="0.91 0.3 0.24 1" />
			</material>
		</visual>
		<collision>
			<origin
				xyz="0 0 0"
				rpy="0 0 0" />
			<geometry>
				<mesh
					filename="package://ardop_description_02/meshes/shoulder_1_link.STL" />
			</geometry>
		</collision>
	</link>

	<joint
		name="shoulder_1_joint"
		type="revolute">
		<origin
			xyz="-0.0281 -0.25288 0.504"
			rpy="0 0 0" />
		<parent
			link="base_link" />
		<child
			link="shoulder_1_link" />
		<axis
			xyz="1 0 0" />
		<limit
			effort="30"
			velocity="3"
			lower="-1.5708"
			upper="1.5708" />
		<dynamics 
			damping="50" 
			friction="1" />
	</joint>

	<link
		name="upper_1_link">
		<inertial>
			<origin
				xyz="-0.00002823 -0.01138195 -0.05092308"
				rpy="0 0 0" />
			<mass
				value="0.158253" />
			<inertia
				ixx="0.0"
				ixy="0.0"
				ixz="0.0"
				iyy="0.0"
				iyz="0.0"
				izz="0.0" />
		</inertial>
		<visual>
			<origin
				xyz="0 0 0"
				rpy="0 0 0" />
			<geometry>
				<mesh
					filename="package://ardop_description_02/meshes/upper_1_link.STL" />
			</geometry>
			<material
				name="red">
				<color
					rgba="0.91 0.3 0.24 1" />
			</material>
		</visual>
		<collision>
			<origin
				xyz="0 0 0"
				rpy="0 0 0" />
			<geometry>
				<mesh
					filename="package://ardop_description_02/meshes/upper_1_link.STL" />
			</geometry>
		</collision>
	</link>

	<joint
		name="upper_1_joint"
		type="revolute">
		<origin
			xyz="0.027024 -0.075963 0.0044026"
			rpy="0 0 0" />
		<parent
			link="shoulder_1_link" />
		<child
			link="upper_1_link" />
		<axis
			xyz="0 1 0" />
		<limit
			effort="30"
			velocity="3"
			lower="-1.5708"
			upper="1.5708" />
		<dynamics 
			damping="50" 
			friction="1" />
	</joint>

	<link
		name="upper_2_link">
		<inertial>
			<origin
				xyz="0.00054343 -0.00051038 -0.01584260"
				rpy="0 0 0" />
			<mass
				value="0.076206" />
			<inertia
				ixx="0.0"
				ixy="0.0"
				ixz="-0.0"
				iyy="0.0"
				iyz="-0.0"
				izz="0.0" />
		</inertial>
		<visual>
			<origin
				xyz="0 0 0"
				rpy="0 0 0" />
			<geometry>
				<mesh
					filename="package://ardop_description_02/meshes/upper_2_link.STL" />
			</geometry>
			<material
				name="red">
				<color
					rgba="0.91 0.3 0.24 1" />
			</material>
		</visual>
		<collision>
			<origin
				xyz="0 0 0"
				rpy="0 0 0" />
			<geometry>
				<mesh
					filename="package://ardop_description_02/meshes/upper_2_link.STL" />
			</geometry>
		</collision>
	</link>

	<joint
		name="upper_2_joint"
		type="revolute">
		<origin
			xyz="9.3209E-05 0 -0.10405"
			rpy="0 0 0" />
		<parent
			link="upper_1_link" />
		<child
			link="upper_2_link" />
		<axis
			xyz="0 0 1" />
		<limit
			effort="30"
			velocity="3"
			lower="-1.5708"
			upper="1.5708" />
		<dynamics 
			damping="50" 
			friction="1" />
	</joint>

	<link
		name="lower_1_link">
		<inertial>
			<origin
				xyz="0 -0.03002602 -0.06443806"
				rpy="0 0 0" />
			<mass
				value="0.2241" />
			<inertia
				ixx="0.0"
				ixy="0"
				ixz="0"
				iyy="0.000001"
				iyz="-0.0"
				izz="0.0" />
		</inertial>
		<visual>
			<origin
				xyz="0 0 0"
				rpy="0 0 0" />
			<geometry>
				<mesh
					filename="package://ardop_description_02/meshes/lower_1_link.STL" />
			</geometry>
			<material
				name="red">
				<color
					rgba="0.91 0.3 0.24 1" />
			</material>
		</visual>
		<collision>
			<origin
				xyz="0 0 0"
				rpy="0 0 0" />
			<geometry>
				<mesh
					filename="package://ardop_description_02/meshes/lower_1_link.STL" />
			</geometry>
		</collision>
	</link>

	<joint
		name="lower_1_joint"
		type="revolute">
		<origin
			xyz="0.0024117 0.025054 -0.070238"
			rpy="0 0 0" />
		<parent
			link="upper_2_link" />
		<child
			link="lower_1_link" />
		<axis
			xyz="0 1 0" />
		<limit
			effort="30"
			velocity="3"
			lower="-1.5708"
			upper="1.5708" />
		<dynamics 
			damping="50" 
			friction="1" />
	</joint>

	<link
		name="lower_2_link">
		<inertial>
			<origin
				xyz="-0.00122183 -0.00357756 -0.05944029"
				rpy="0 0 0" />
			<mass
				value="0.178" />
			<inertia
				ixx="0.000002"
				ixy="-0.0"
				ixz="-0.0"
				iyy="0.000002"
				iyz="-0.0"
				izz="0.0" />
		</inertial>
		<visual>
			<origin
				xyz="0 0 0"
				rpy="0 0 0" />
			<geometry>
				<mesh
					filename="package://ardop_description_02/meshes/lower_2_link.STL" />
			</geometry>
			<material
				name="red">
				<color
					rgba="0.91 0.3 0.24 1" />
			</material>
		</visual>
		<collision>
			<origin
				xyz="0 0 0"
				rpy="0 0 0" />
			<geometry>
				<mesh
					filename="package://ardop_description_02/meshes/lower_2_link.STL" />
			</geometry>
		</collision>
	</link>

	<joint
		name="lower_2_joint"
		type="revolute">
		<origin
			xyz="0 -0.030211 -0.12948"
			rpy="0 0 0" />
		<parent
			link="lower_1_link" />
		<child
			link="lower_2_link" />
		<axis
			xyz="0 0 1" />
		<limit
			effort="30"
			velocity="3"
			lower="-1.5708"
			upper="1.5708" />
		<dynamics 
			damping="50" 
			friction="1" />
	</joint>

	<link
		name="end_effector_link">
		<inertial>
			<origin
				xyz="-0.01777538 0.01874637 -0.04534066"
				rpy="0 0 0" />
			<mass
				value="0.010303" />
			<inertia
				ixx="0.0"
				ixy="0.0"
				ixz="-0.0"
				iyy="0.0"
				iyz="0.0"
				izz="0.0" />
		</inertial>
		<visual>
			<origin
				xyz="0 0 0"
				rpy="0 0 0" />
			<geometry>
				<mesh
					filename="package://ardop_description_02/meshes/end_effector_link.STL" />
			</geometry>
			<material
				name="blue">
				<color
					rgba="0.2 0.6 0.86 1" />
			</material>
		</visual>
		<collision>
			<origin
				xyz="0 0 0"
				rpy="0 0 0" />
			<geometry>
				<mesh
					filename="package://ardop_description_02/meshes/end_effector_link.STL" />
			</geometry>
		</collision>
	</link>

	<joint
		name="end_effector_joint"
		type="revolute">
		<origin
			xyz="0.020552 0.011541 -0.12357"
			rpy="0 0 0" />
		<parent
			link="lower_2_link" />
		<child
			link="end_effector_link" />
		<axis
			xyz="1 0 0" />
		<limit
			effort="30"
			velocity="3"
			lower="-0.6"
			upper="1.5708" />
		<dynamics 
			damping="50" 
			friction="1" />
	</joint>
 
	<gazebo reference="base_link">
		<mu1 value="0.7"/>
		<mu2 value="0.7"/>
		<kp value="10000000.0"/>
		<kd value="1.0"/>
		<material>Gazebo/White</material>
		<turnGravityOff>false</turnGravityOff>
	</gazebo>

	<gazebo reference="wheel_front_left_link">
		<mu1 value="0.7"/>
		<mu2 value="0.7"/>
		<kp value="10000000.0"/>
		<kd value="1.0"/>
		<fdir1 value="1 0 0"/>
		<material>Gazebo/Grey</material>
		<turnGravityOff>false</turnGravityOff>
	</gazebo>

	<gazebo reference="wheel_front_right_link">
		<mu1 value="0.7"/>
		<mu2 value="0.7"/>
		<kp value="10000000.0"/>
		<kd value="1.0"/>
		<fdir1 value="1 0 0"/>
		<material>Gazebo/Grey</material>
		<turnGravityOff>false</turnGravityOff>
	</gazebo>

	<gazebo reference="wheel_back_left_link">
		<mu1 value="0.7"/>
		<mu2 value="0.7"/>
		<kp value="10000000.0"/>
		<kd value="1.0"/>
		<fdir1 value="1 0 0"/>
		<material>Gazebo/Grey</material>
		<turnGravityOff>false</turnGravityOff>
	</gazebo>

	<gazebo reference="wheel_back_right_link">
		<mu1 value="0.7"/>
		<mu2 value="0.7"/>
		<kp value="10000000.0"/>
		<kd value="1.0"/>
		<fdir1 value="1 0 0"/>
		<material>Gazebo/Grey</material>
		<turnGravityOff>false</turnGravityOff>
	</gazebo>

	<transmission name="wheel_front_left_joint_trans">
		<type>transmission_interface/SimpleTransmission</type>
		<joint 
			name="wheel_front_left_joint" />
		<actuator 
			name="wheel_front_left_motor">
			<hardwareInterface>EffortJointInterface</hardwareInterface>
			<mechanicalReduction>1</mechanicalReduction>
		</actuator>
	</transmission>

	<transmission name="wheel_front_right_joint_trans">
		<type>transmission_interface/SimpleTransmission</type>
		<joint 
			name="wheel_front_right_joint" />
		<actuator 
			name="wheel_front_right_motor">
			<hardwareInterface>EffortJointInterface</hardwareInterface>
			<mechanicalReduction>1</mechanicalReduction>
		</actuator>
	</transmission>

	<transmission name="wheel_back_left_joint_trans">
		<type>transmission_interface/SimpleTransmission</type>
		<joint 
			name="wheel_back_left_joint" />
		<actuator 
			name="wheel_back_left_motor">
			<hardwareInterface>EffortJointInterface</hardwareInterface>
			<mechanicalReduction>1</mechanicalReduction>
		</actuator>
	</transmission>

	<transmission name="wheel_back_right_joint_trans">
		<type>transmission_interface/SimpleTransmission</type>
		<joint 
			name="wheel_back_right_joint" />
		<actuator 
			name="wheel_back_right_motor">
			<hardwareInterface>EffortJointInterface</hardwareInterface>
			<mechanicalReduction>1</mechanicalReduction>
		</actuator>
	</transmission>

	 <gazebo reference="shoulder_1_link">
		<mu1 value="0.7"/>
		<mu2 value="0.7"/>
		<kp value="10000000.0"/>
		<kd value="1.0"/>
		<material>Gazebo/Red</material>
		<turnGravityOff>false</turnGravityOff>
	</gazebo>

	<gazebo reference="upper_1_link">
		<mu1 value="0.7"/>
		<mu2 value="0.7"/>
		<kp value="10000000.0"/>
		<kd value="1.0"/>
		<material>Gazebo/Red</material>
		<turnGravityOff>false</turnGravityOff>
	</gazebo>

	<gazebo reference="upper_2_link">
		<mu1 value="0.7"/>
		<mu2 value="0.7"/>
		<kp value="10000000.0"/>
		<kd value="1.0"/>
		<material>Gazebo/Red</material>
		<turnGravityOff>false</turnGravityOff>
	</gazebo>

	<gazebo reference="lower_1_link">
		<mu1 value="0.7"/>
		<mu2 value="0.7"/>
		<kp value="10000000.0"/>
		<kd value="1.0"/>
		<material>Gazebo/Red</material>
		<turnGravityOff>false</turnGravityOff>
	</gazebo>

	<gazebo reference="lower_2_link">
		<mu1 value="0.7"/>
		<mu2 value="0.7"/>
		<kp value="10000000.0"/>
		<kd value="1.0"/>
		<material>Gazebo/Red</material>
		<turnGravityOff>false</turnGravityOff>
	</gazebo>

	<gazebo reference="end_effector_link">
		<mu1 value="0.7"/>
		<mu2 value="0.7"/>
		<kp value="10000000.0"/>
		<kd value="1.0"/>
		<material>Gazebo/Blue</material>
		<turnGravityOff>false</turnGravityOff>
	</gazebo> 

</robot>
