<?xml version="1.0" encoding="UTF-8"?>
<robot
	name="ardop">

	<link name="odom" />

	<link
		name="chassis_link">
		<inertial>
			<origin
				xyz="-0.05669211 -0.00059544 0.13127776"
				rpy="0 0 0" />
			<mass
				value="6" />
			<inertia
				ixx="0.000325"
				ixy="0.0"
				ixz="-0.000054"
				iyy="0.000398"
				iyz="-0.018212"
				izz="0.000293" />
		</inertial>
		<visual>
			<origin
				xyz="0 0 0"
				rpy="0 0 0" />
			<geometry>
				<mesh
					filename="package://ardop_description/meshes/chassis_link.STL" />
			</geometry>
			<material
				name="cream">
				<color
					rgba="0.93 0.94 0.95 1" />
			</material>
		</visual>
		<collision>
			<origin
				xyz="0 0 0"
				rpy="0 0 0" />
			<geometry>
				<mesh
					filename="package://ardop_description/meshes/chassis_link.STL" />
			</geometry>
		</collision>
	</link>

	<joint
		name="odom_joint"
		type="fixed">
		<parent
			link="odom" />
		<child
			link="chassis_link" />
	</joint>

	<link
		name="wheel_front_left_link">
		<inertial>
			<origin
				xyz="0 0.02096815 0"
				rpy="0 0 0" />
			<mass
				value="0.4" />
			<inertia
				ixx="0"
				ixy="0"
				ixz="0"
				iyy="0"
				iyz="0"
				izz="0" />
		</inertial>
		<visual>
			<origin
				xyz="0 0 0"
				rpy="0 0 0" />
			<geometry>
				<mesh
					filename="package://ardop_description/meshes/wheel_front_left_link.STL" />
			</geometry>
			<material
				name="dark_blue">
				<color
					rgba="0.17 0.24 0.31 1" />
			</material>
		</visual>
		<collision>
			<origin
				xyz="0 0 0"
				rpy="0 0 0" />
			<geometry>
				<mesh
					filename="package://ardop_description/meshes/wheel_front_left_link.STL" />
			</geometry>
		</collision>
	</link>

	<joint
		name="wheel_front_left_joint"
		type="continuous">
		<origin
			xyz="0.03 0.1895 0.05"
			rpy="0 0 0" />
		<parent
			link="chassis_link" />
		<child
			link="wheel_front_left_link" />
		<axis
			xyz="0 1 0" />
		<limit
			effort="100"
			velocity="100" />
		<safety_controller
			k_velocity="10" />
	</joint>

	<link
		name="wheel_front_right_link">
		<inertial>
			<origin
				xyz="0 -0.02096815 0"
				rpy="0 0 0" />
			<mass
				value="0.4" />
			<inertia
				ixx="0"
				ixy="0"
				ixz="0"
				iyy="0"
				iyz="0"
				izz="0" />
		</inertial>
		<visual>
			<origin
				xyz="0 0 0"
				rpy="0 0 0" />
			<geometry>
				<mesh
					filename="package://ardop_description/meshes/wheel_front_right_link.STL" />
			</geometry>
			<material
				name="dark_blue">
				<color
					rgba="0.17 0.24 0.31 1" />
			</material>
		</visual>
		<collision>
			<origin
				xyz="0 0 0"
				rpy="0 0 0" />
			<geometry>
				<mesh
					filename="package://ardop_description/meshes/wheel_front_right_link.STL" />
			</geometry>
		</collision>
	</link>

	<joint
		name="wheel_front_right_joint"
		type="continuous">
		<origin
			xyz="0.03 -0.1895 0.05"
			rpy="0 0 0" />
		<parent
			link="chassis_link" />
		<child
			link="wheel_front_right_link" />
		<axis
			xyz="0 1 0" />
		<limit
			effort="100"
			velocity="100" />
		<safety_controller
			k_velocity="10" />
	</joint>

	<link
		name="wheel_back_left_link">
		<inertial>
			<origin
				xyz="0 0.02096815 0"
				rpy="0 0 0" />
			<mass
				value="0.4" />
			<inertia
				ixx="0"
				ixy="0"
				ixz="0"
				iyy="0"
				iyz="0"
				izz="0" />
		</inertial>
		<visual>
			<origin
				xyz="0 0 0"
				rpy="0 0 0" />
			<geometry>
				<mesh
					filename="package://ardop_description/meshes/wheel_back_left_link.STL" />
			</geometry>
			<material
				name="dark_blue">
				<color
					rgba="0.17 0.24 0.31 1" />
			</material>
		</visual>
		<collision>
			<origin
				xyz="0 0 0"
				rpy="0 0 0" />
			<geometry>
				<mesh
					filename="package://ardop_description/meshes/wheel_back_left_link.STL" />
			</geometry>
		</collision>
	</link>

	<joint
		name="wheel_back_left_joint"
		type="continuous">
		<origin
			xyz="-0.2 0.1895 0.05"
			rpy="0 0 0" />
		<parent
			link="chassis_link" />
		<child
			link="wheel_back_left_link" />
		<axis
			xyz="0 1 0" />
		<limit
			effort="100"
			velocity="100" />
		<safety_controller
			k_velocity="10" />
	</joint>

	<link
		name="wheel_back_right_link">
		<inertial>
			<origin
				xyz="0 -0.02096815 0"
				rpy="0 0 0" />
			<mass
				value="0.4" />
			<inertia
				ixx="0"
				ixy="0"
				ixz="0"
				iyy="0"
				iyz="0"
				izz="0" />
		</inertial>
		<visual>
			<origin
				xyz="0 0 0"
				rpy="0 0 0" />
			<geometry>
				<mesh
					filename="package://ardop_description/meshes/wheel_back_right_link.STL" />
			</geometry>
			<material
				name="dark_blue">
				<color
					rgba="0.17 0.24 0.31 1" />
			</material>
		</visual>
		<collision>
			<origin
				xyz="0 0 0"
				rpy="0 0 0" />
			<geometry>
				<mesh
					filename="package://ardop_description/meshes/wheel_back_right_link.STL" />
			</geometry>
		</collision>
	</link>

	<joint
		name="wheel_back_right_joint"
		type="continuous">
		<origin
			xyz="-0.2 -0.1895 0.05"
			rpy="0 0 0" />
		<parent
			link="chassis_link" />
		<child
			link="wheel_back_right_link" />
		<axis
			xyz="0 1 0" />
		<limit
			effort="100"
			velocity="100" />
		<safety_controller
			k_velocity="10" />
	</joint>

	<link
		name="shoulder_1_link">
		<inertial>
			<origin
				xyz="0.0034325 -0.035582 -0.027791"
				rpy="0 0 0" />
			<mass
				value="0.1" />
			<inertia
				ixx="0"
				ixy="0"
				ixz="0"
				iyy="0"
				iyz="0"
				izz="0" />
		</inertial>
		<visual>
			<origin
				xyz="0 0 0"
				rpy="0 0 0" />
			<geometry>
				<mesh
					filename="package://ardop_description/meshes/shoulder_1_link.STL" />
			</geometry>
			<material
				name="red">
				<color
					rgba="0.91 0.3 0.24 1" />
			</material>
		</visual>
		<collision>
			<origin
				xyz="0 0 0"
				rpy="0 0 0" />
			<geometry>
				<mesh
					filename="package://ardop_description/meshes/shoulder_1_link.STL" />
			</geometry>
		</collision>
	</link>

	<joint
		name="shoulder_1_joint"
		type="revolute">
		<origin
			xyz="-0.002 -0.25288 0.5401"
			rpy="0 0 0" />
		<parent
			link="chassis_link" />
		<child
			link="shoulder_1_link" />
		<axis
			xyz="0 0 1" />
		<limit
			effort="300"
			velocity="3"
			lower="-1.5708"
			upper="1.5708" />
		<dynamics 
			damping="50" 
			friction="1" />
	</joint>

	<link
		name="upper_1_link">
		<inertial>
			<origin
				xyz="0.00050398 -0.080501 0.0070176"
				rpy="0 0 0" />
			<mass
				value="0.1" />
			<inertia
				ixx="0"
				ixy="0"
				ixz="0"
				iyy="0"
				iyz="0"
				izz="0" />
		</inertial>
		<visual>
			<origin
				xyz="0 0 0"
				rpy="0 0 0" />
			<geometry>
				<mesh
					filename="package://ardop_description/meshes/upper_1_link.STL" />
			</geometry>
			<material
				name="red">
				<color
					rgba="0.91 0.3 0.24 1" />
			</material>
		</visual>
		<collision>
			<origin
				xyz="0 0 0"
				rpy="0 0 0" />
			<geometry>
				<mesh
					filename="package://ardop_description/meshes/upper_1_link.STL" />
			</geometry>
		</collision>
	</link>

	<joint
		name="upper_1_joint"
		type="revolute">
		<origin
			xyz="0.0027 -0.075963 -0.026697"
			rpy="1.5708 0 0" />
		<parent
			link="shoulder_1_link" />
		<child
			link="upper_1_link" />
		<axis
			xyz="0 0 -1" />
		<limit
			effort="300"
			velocity="3"
			lower="-1.5708"
			upper="1.5708" />
		<dynamics 
			damping="50" 
			friction="1" />
	</joint>

	<link
		name="lower_1_link">
		<inertial>
			<origin
				xyz="0.064437 2.5671E-07 -0.030026"
				rpy="0 0 0" />
			<mass
				value="0.1" />
			<inertia
				ixx="0"
				ixy="0"
				ixz="0"
				iyy="0"
				iyz="0"
				izz="0" />
		</inertial>
		<visual>
			<origin
				xyz="0 0 0"
				rpy="0 0 0" />
			<geometry>
				<mesh
					filename="package://ardop_description/meshes/lower_1_link.STL" />
			</geometry>
			<material
				name="red">
				<color
					rgba="0.91 0.3 0.24 1" />
			</material>
		</visual>
		<collision>
			<origin
				xyz="0 0 0"
				rpy="0 0 0" />
			<geometry>
				<mesh
					filename="package://ardop_description/meshes/lower_1_link.STL" />
			</geometry>
		</collision>
	</link>

	<joint
		name="lower_1_joint"
		type="revolute">
		<origin
			xyz="0.00017493 -0.17353 -0.025178"
			rpy="3.1416 0 -1.5708" />
		<parent
			link="upper_1_link" />
		<child
			link="lower_1_link" />
		<axis
			xyz="0 0 1" />
		<limit
			effort="300"
			velocity="3"
			lower="-1.5708"
			upper="1.5708" />
		<dynamics 
			damping="50" 
			friction="1" />
	</joint>

	<link
		name="lower_2_link">
		<inertial>
			<origin
				xyz="0.00040034 -0.00018685 0.04614"
				rpy="0 0 0" />
			<mass
				value="0.1" />
			<inertia
				ixx="0"
				ixy="0"
				ixz="0"
				iyy="0"
				iyz="0"
				izz="0" />
		</inertial>
		<visual>
			<origin
				xyz="0 0 0"
				rpy="0 0 0" />
			<geometry>
				<mesh
					filename="package://ardop_description/meshes/lower_2_link.STL" />
			</geometry>
			<material
				name="red">
				<color
					rgba="0.91 0.3 0.24 1" />
			</material>
		</visual>
		<collision>
			<origin
				xyz="0 0 0"
				rpy="0 0 0" />
			<geometry>
				<mesh
					filename="package://ardop_description/meshes/lower_2_link.STL" />
			</geometry>
		</collision>
	</link>

	<joint
		name="lower_2_joint"
		type="revolute">
		<origin
			xyz="0.12948 0 -0.030211"
			rpy="-1.5708 0 -1.5708" />
		<parent
			link="lower_1_link" />
		<child
			link="lower_2_link" />
		<axis
			xyz="0 0 -1" />
		<limit
			effort="300"
			velocity="3"
			lower="-1.5708"
			upper="1.5708" />
		<dynamics 
			damping="50" 
			friction="1" />
	</joint>

	<link
		name="ee_pitch_link">
		<inertial>
			<origin
				xyz="-0.0045175 -0.0046268 0.014845"
				rpy="0 0 0" />
			<mass
				value="0.1" />
			<inertia
				ixx="0"
				ixy="0"
				ixz="0"
				iyy="0"
				iyz="0"
				izz="0" />
		</inertial>
		<visual>
			<origin
				xyz="0 0 0"
				rpy="0 0 0" />
			<geometry>
				<mesh
					filename="package://ardop_description/meshes/ee_pitch_link.STL" />
			</geometry>
			<material
				name="red">
				<color
					rgba="0.91 0.3 0.24 1" />
			</material>
		</visual>
		<collision>
			<origin
				xyz="0 0 0"
				rpy="0 0 0" />
			<geometry>
				<mesh
					filename="package://ardop_description/meshes/ee_pitch_link.STL" />
			</geometry>
		</collision>
	</link>

	<joint
		name="ee_pitch_joint"
		type="revolute">
		<origin
			xyz="0.011877 -0.028151 0.11857"
			rpy="-1.5708 0 -3.1416" />
		<parent
			link="lower_2_link" />
		<child
			link="ee_pitch_link" />
		<axis
			xyz="0 0 1" />
		<limit
			effort="300"
			velocity="3"
			lower="-0.785398"
			upper="2.35619" />
		<dynamics 
			damping="50" 
			friction="1" />
	</joint>

	<link
		name="ee_roll_link">
		<inertial>
			<origin
				xyz="-0.0047287 0.054125 0.037222"
				rpy="0 0 0" />
			<mass
				value="0.1" />
			<inertia
				ixx="0"
				ixy="0"
				ixz="0"
				iyy="0"
				iyz="0"
				izz="0" />
		</inertial>
		<visual>
			<origin
				xyz="0 0 0"
				rpy="0 0 0" />
			<geometry>
				<mesh
					filename="package://ardop_description/meshes/ee_roll_link.STL" />
			</geometry>
			<material
				name="blue">
				<color
					rgba="0.2 0.6 0.86 1" />
			</material>
		</visual>
		<collision>
			<origin
				xyz="0 0 0"
				rpy="0 0 0" />
			<geometry>
				<mesh
					filename="package://ardop_description/meshes/ee_roll_link.STL" />
			</geometry>
		</collision>
	</link>

	<joint
		name="ee_roll_joint"
		type="revolute">
		<origin
			xyz="-0.0311 -0.014379 0.017"
			rpy="-1.5708 0 1.5708" />
		<parent
			link="ee_pitch_link" />
		<child
			link="ee_roll_link" />
		<axis
			xyz="0 0 1" />
		<limit
			effort="300"
			velocity="3"
			lower="-1.5708"
			upper="1.5708" />
		<dynamics 
			damping="50" 
			friction="1" />
	</joint>

	<link
		name="end_effector_link">
		<inertial>
			<origin
				xyz="0.018746 -0.045341 -0.017775"
				rpy="0 0 0" />
			<mass
				value="0.1" />
			<inertia
				ixx="0"
				ixy="0"
				ixz="0"
				iyy="0"
				iyz="0"
				izz="0" />
		</inertial>
		<visual>
			<origin
				xyz="0 0 0"
				rpy="0 0 0" />
			<geometry>
				<mesh
					filename="package://ardop_description/meshes/end_effector_link.STL" />
			</geometry>
			<material
				name="blue">
				<color
					rgba="0.2 0.6 0.86 1" />
			</material>
		</visual>
		<collision>
			<origin
				xyz="0 0 0"
				rpy="0 0 0" />
			<geometry>
				<mesh
					filename="package://ardop_description/meshes/end_effector_link.STL" />
			</geometry>
		</collision>
	</link>

	<joint
		name="end_effector_joint"
		type="revolute">
		<origin
			xyz="0.02055 0.030611 0.034"
			rpy="-1.5708 0 -1.5708" />
		<parent
			link="ee_roll_link" />
		<child
			link="end_effector_link" />
		<axis
			xyz="0 0 1" />
		<limit
			effort="300"
			velocity="3"
			lower="-0.6"
			upper="1.5708" />
		<dynamics 
			damping="50" 
			friction="1" />
	</joint>

	<gazebo 
		reference="odom">
	</gazebo>

	<gazebo reference="chassis_link">
		<material>Gazebo/White</material>
		<turnGravityOff>false</turnGravityOff>
	</gazebo>

	<gazebo reference="wheel_front_left_link">
		<!--fdir1 value="1 0 0"/-->
		<material>Gazebo/Grey</material>
		<turnGravityOff>false</turnGravityOff>
	</gazebo>

	<gazebo reference="wheel_front_right_link">
		<!--fdir1 value="1 0 0"/-->
		<material>Gazebo/Grey</material>
		<turnGravityOff>false</turnGravityOff>
	</gazebo>

	<gazebo reference="wheel_back_left_link">
		<!--fdir1 value="1 0 0"/-->
		<material>Gazebo/Grey</material>
		<turnGravityOff>false</turnGravityOff>
	</gazebo>

	<gazebo reference="wheel_back_right_link">
		<!--fdir1 value="1 0 0"/-->
		<material>Gazebo/Grey</material>
		<turnGravityOff>false</turnGravityOff>
	</gazebo>

	<gazebo reference="shoulder_1_link">
		<material>Gazebo/Red</material>
		<turnGravityOff>false</turnGravityOff>
	</gazebo>

	<gazebo reference="upper_1_link">
		<material>Gazebo/Red</material>
		<turnGravityOff>false</turnGravityOff>
	</gazebo>

	<gazebo reference="upper_2_link">
		<material>Gazebo/Red</material>
		<turnGravityOff>false</turnGravityOff>
	</gazebo>

	<gazebo reference="lower_1_link">
		<material>Gazebo/Red</material>
		<turnGravityOff>false</turnGravityOff>
	</gazebo>

	<gazebo reference="lower_2_link">
		<material>Gazebo/Red</material>
		<turnGravityOff>false</turnGravityOff>
	</gazebo>

	<gazebo reference="ee_pitch_link">
		<material>Gazebo/Red</material>
		<turnGravityOff>false</turnGravityOff>
	</gazebo>

	<gazebo reference="ee_roll_link">
		<material>Gazebo/Blue</material>
		<turnGravityOff>false</turnGravityOff>
	</gazebo>

	<gazebo reference="end_effector_link">
		<material>Gazebo/Blue</material>
		<turnGravityOff>false</turnGravityOff>
	</gazebo>

	<gazebo>
		<plugin name="gazebo_ros_control" filename="libgazebo_ros_control.so">
			<robotNamespace>/ardop</robotNamespace>
			<robotSimType>gazebo_ros_control/DefaultRobotHWSim</robotSimType>
		</plugin>
	</gazebo>

	<transmission name="wheel_front_left_joint_trans">
		<type>transmission_interface/SimpleTransmission</type>
		<joint name="wheel_front_left_joint">
			<hardwareInterface>hardware_interface/EffortJointInterface</hardwareInterface>
		</joint>
		<actuator name="wheel_front_left_motor">
			<hardwareInterface>hardware_interface/EffortJointInterface</hardwareInterface>
			<mechanicalReduction>1</mechanicalReduction>
		</actuator>
	</transmission>

	<transmission name="wheel_front_right_joint_trans">
		<type>transmission_interface/SimpleTransmission</type>
		<joint name="wheel_front_right_joint">
			<hardwareInterface>hardware_interface/EffortJointInterface</hardwareInterface>
		</joint>
		<actuator name="wheel_front_right_motor">
			<hardwareInterface>hardware_interface/EffortJointInterface</hardwareInterface>
			<mechanicalReduction>1</mechanicalReduction>
		</actuator>
	</transmission>

	<transmission name="wheel_back_left_joint_trans">
		<type>transmission_interface/SimpleTransmission</type>
		<joint name="wheel_back_left_joint">
			<hardwareInterface>hardware_interface/EffortJointInterface</hardwareInterface>
		</joint>
		<actuator name="wheel_back_left_motor">
			<hardwareInterface>hardware_interface/EffortJointInterface</hardwareInterface>
			<mechanicalReduction>1</mechanicalReduction>
		</actuator>
	</transmission>

	<transmission name="wheel_back_right_joint_trans">
		<type>transmission_interface/SimpleTransmission</type>
		<joint name="wheel_back_right_joint">
			<hardwareInterface>hardware_interface/EffortJointInterface</hardwareInterface>
		</joint>
		<actuator name="wheel_back_right_motor">
			<hardwareInterface>hardware_interface/EffortJointInterface</hardwareInterface>
			<mechanicalReduction>1</mechanicalReduction>
		</actuator>
	</transmission>

	<transmission name="shoulder_1_joint_trans">
		<type>transmission_interface/SimpleTransmission</type>
		<joint name="shoulder_1_joint">
			<hardwareInterface>hardware_interface/PositionJointInterface</hardwareInterface>
		</joint>
		<actuator name="shoulder_1_servo">
			<hardwareInterface>hardware_interface/PositionJointInterface</hardwareInterface>
			<mechanicalReduction>1</mechanicalReduction>
		</actuator>
	</transmission>

	<transmission name="upper_1_joint_trans">
		<type>transmission_interface/SimpleTransmission</type>
		<joint name="upper_1_joint">
			<hardwareInterface>hardware_interface/PositionJointInterface</hardwareInterface>
		</joint>
		<actuator name="upper_1_servo">
			<hardwareInterface>hardware_interface/PositionJointInterface</hardwareInterface>
			<mechanicalReduction>1</mechanicalReduction>
		</actuator>
	</transmission>

	<transmission name="lower_1_joint_trans">
		<type>transmission_interface/SimpleTransmission</type>
		<joint name="lower_1_joint">
			<hardwareInterface>hardware_interface/PositionJointInterface</hardwareInterface>
		</joint>
		<actuator name="lower_1_servo">
			<hardwareInterface>hardware_interface/PositionJointInterface</hardwareInterface>
			<mechanicalReduction>1</mechanicalReduction>
		</actuator>
	</transmission>

	<transmission name="lower_2_joint_trans">
		<type>transmission_interface/SimpleTransmission</type>
		<joint name="lower_2_joint">
			<hardwareInterface>hardware_interface/PositionJointInterface</hardwareInterface>
		</joint>
		<actuator name="lower_2_servo">
			<hardwareInterface>hardware_interface/PositionJointInterface</hardwareInterface>
			<mechanicalReduction>1</mechanicalReduction>
		</actuator>
	</transmission>

	<transmission name="ee_pitch_joint_trans">
		<type>transmission_interface/SimpleTransmission</type>
		<joint name="ee_pitch_joint">
			<hardwareInterface>hardware_interface/PositionJointInterface</hardwareInterface>
		</joint>
		<actuator name="ee_pitch_servo">
			<hardwareInterface>hardware_interface/PositionJointInterface</hardwareInterface>
			<mechanicalReduction>1</mechanicalReduction>
		</actuator>
	</transmission>

	<transmission name="ee_roll_joint_trans">
		<type>transmission_interface/SimpleTransmission</type>
		<joint name="ee_roll_joint">
			<hardwareInterface>hardware_interface/PositionJointInterface</hardwareInterface>
		</joint>
		<actuator name="ee_roll_servo">
			<hardwareInterface>hardware_interface/PositionJointInterface</hardwareInterface>
			<mechanicalReduction>1</mechanicalReduction>
		</actuator>
	</transmission>

	<transmission name="end_effector_joint_trans">
		<type>transmission_interface/SimpleTransmission</type>
		<joint name="end_effector_joint">
			<hardwareInterface>hardware_interface/PositionJointInterface</hardwareInterface>
		</joint>
		<actuator name="end_effector_servo">
			<hardwareInterface>hardware_interface/PositionJointInterface</hardwareInterface>
			<mechanicalReduction>1</mechanicalReduction>
		</actuator>
	</transmission>

</robot>
