<?xml version="1.0" encoding="UTF-8"?>
<robot
	name="ardop_description_01">
	<link
		name="base_link">
		<inertial>
			<origin
				xyz="-0.00059544 0.056692 0.13128"
				rpy="0 0 0" />
			<mass
				value="6" />
			<inertia
				ixx="0.025908"
				ixy="-0.00043576"
				ixz="0.0029902"
				iyy="0.027256"
				iyz="0.0039098"
				izz="0.0025574" />
		</inertial>
		<visual>
			<origin
				xyz="0 0 0"
				rpy="0 0 0" />
			<geometry>
				<mesh
					filename="package://ardop_description_01/meshes/base_link.STL" />
			</geometry>
			<material
				name="cream">
				<color
					rgba="0.93 0.94 0.95 1" />
			</material>
		</visual>
		<collision>
			<origin
				xyz="0 0 0"
				rpy="0 0 0" />
			<geometry>
				<mesh
					filename="package://ardop_description_01/meshes/base_link.STL" />
			</geometry>
		</collision>
	</link>
	<link
		name="wheel_front_left_link">
		<inertial>
			<origin
				xyz="-3.0531E-16 -6.5919E-17 -0.020968"
				rpy="0 0 0" />
			<mass
				value="0.32836" />
			<inertia
				ixx="0"
				ixy="0"
				ixz="0"
				iyy="0"
				iyz="0"
				izz="0" />
		</inertial>
		<visual>
			<origin
				xyz="0 0 0"
				rpy="0 0 0" />
			<geometry>
				<mesh
					filename="package://ardop_description_01/meshes/wheel_front_left_link.STL" />
			</geometry>
			<material
				name="dark_blue">
				<color
					rgba="0.17 0.24 0.31 1" />
			</material>
		</visual>
		<collision>
			<origin
				xyz="0 0 0"
				rpy="0 0 0" />
			<geometry>
				<mesh
					filename="package://ardop_description_01/meshes/wheel_front_left_link.STL" />
			</geometry>
		</collision>
	</link>
	<joint
		name="wheel_front_left_joint"
		type="continuous">
		<origin
			xyz="0.1895 -0.03 0.05"
			rpy="3.1416 1.5708 0" />
		<parent
			link="base_link" />
		<child
			link="wheel_front_left_link" />
		<axis
			xyz="0 0 -1" />
		<limit
			effort="100"
			velocity="100" />
		<dynamics
			damping="0.05"
			friction="0.7" />
		<safety_controller
			k_velocity="10" />
	</joint>
	<link
		name="wheel_front_right_link">
		<inertial>
			<origin
				xyz="2.9837E-16 -2.1858E-16 -0.020968"
				rpy="0 0 0" />
			<mass
				value="0.32836" />
			<inertia
				ixx="0"
				ixy="0"
				ixz="0"
				iyy="0"
				iyz="0"
				izz="0" />
		</inertial>
		<visual>
			<origin
				xyz="0 0 0"
				rpy="0 0 0" />
			<geometry>
				<mesh
					filename="package://ardop_description_01/meshes/wheel_front_right_link.STL" />
			</geometry>
			<material
				name="dark_blue">
				<color
					rgba="0.17 0.24 0.31 1" />
			</material>
		</visual>
		<collision>
			<origin
				xyz="0 0 0"
				rpy="0 0 0" />
			<geometry>
				<mesh
					filename="package://ardop_description_01/meshes/wheel_front_right_link.STL" />
			</geometry>
		</collision>
	</link>
	<joint
		name="wheel_front_right_joint"
		type="continuous">
		<origin
			xyz="-0.1895 -0.03 0.05"
			rpy="0 1.5708 0" />
		<parent
			link="base_link" />
		<child
			link="wheel_front_right_link" />
		<axis
			xyz="0 0 1" />
		<limit
			effort="100"
			velocity="100" />
		<dynamics
			damping="0.05"
			friction="0.7" />
		<safety_controller
			k_velocity="10" />
	</joint>
	<link
		name="wheel_back_left_link">
		<inertial>
			<origin
				xyz="-2.98372437868011E-16 -8.32667268468867E-17 -0.020968152706957"
				rpy="0 0 0" />
			<mass
				value="0.328364573802354" />
			<inertia
				ixx="0"
				ixy="0"
				ixz="0"
				iyy="0"
				iyz="0"
				izz="0" />
		</inertial>
		<visual>
			<origin
				xyz="0 0 0"
				rpy="0 0 0" />
			<geometry>
				<mesh
					filename="package://ardop_description_01/meshes/wheel_back_left_link.STL" />
			</geometry>
			<material
				name="dark_blue">
				<color
					rgba="0.17 0.24 0.31 1" />
			</material>
		</visual>
		<collision>
			<origin
				xyz="0 0 0"
				rpy="0 0 0" />
			<geometry>
				<mesh
					filename="package://ardop_description_01/meshes/wheel_back_left_link.STL" />
			</geometry>
		</collision>
	</link>
	<joint
		name="wheel_back_left_joint"
		type="continuous">
		<origin
			xyz="0.1895 0.2 0.05"
			rpy="3.1416 1.5708 0" />
		<parent
			link="base_link" />
		<child
			link="wheel_back_left_link" />
		<axis
			xyz="0 0 -1" />
		<limit
			effort="100"
			velocity="100" />
		<dynamics
			damping="0.05"
			friction="0.7" />
		<safety_controller
			k_velocity="10" />
	</joint>
	<link
		name="wheel_back_right_link">
		<inertial>
			<origin
				xyz="3.0531E-16 -2.2204E-16 -0.020968"
				rpy="0 0 0" />
			<mass
				value="0.32836" />
			<inertia
				ixx="0"
				ixy="0"
				ixz="0"
				iyy="0"
				iyz="0"
				izz="0" />
		</inertial>
		<visual>
			<origin
				xyz="0 0 0"
				rpy="0 0 0" />
			<geometry>
				<mesh
					filename="package://ardop_description_01/meshes/wheel_back_right_link.STL" />
			</geometry>
			<material
				name="dark_blue">
				<color
					rgba="0.17 0.24 0.31 1" />
			</material>
		</visual>
		<collision>
			<origin
				xyz="0 0 0"
				rpy="0 0 0" />
			<geometry>
				<mesh
					filename="package://ardop_description_01/meshes/wheel_back_right_link.STL" />
			</geometry>
		</collision>
	</link>
	<joint
		name="wheel_back_right_joint"
		type="continuous">
		<origin
			xyz="-0.1895 0.2 0.05"
			rpy="0 1.5708 0" />
		<parent
			link="base_link" />
		<child
			link="wheel_back_right_link" />
		<axis
			xyz="0 0 1" />
		<limit
			effort="100"
			velocity="100" />
		<dynamics
			damping="0.05"
			friction="0.7" />
		<safety_controller
			k_velocity="10" />
	</joint>
	<link
		name="shoulder_1_link">
		<inertial>
			<origin
				xyz="-0.035582 -0.0033945 -0.027863"
				rpy="0 0 0" />
			<mass
				value="0.41" />
			<inertia
				ixx="2.8743E-06"
				ixy="7.6199E-07"
				ixz="3.0692E-07"
				iyy="8.7606E-05"
				iyz="-2.8736E-07"
				izz="8.9476E-05" />
		</inertial>
		<visual>
			<origin
				xyz="0 0 0"
				rpy="0 0 0" />
			<geometry>
				<mesh
					filename="package://ardop_description_01/meshes/shoulder_1_link.STL" />
			</geometry>
			<material
				name="red">
				<color
					rgba="0.91 0.3 0.24 1" />
			</material>
		</visual>
		<collision>
			<origin
				xyz="0 0 0"
				rpy="0 0 0" />
			<geometry>
				<mesh
					filename="package://ardop_description_01/meshes/shoulder_1_link.STL" />
			</geometry>
		</collision>
	</link>
	<joint
		name="shoulder_1_joint"
		type="revolute">
		<origin
			xyz="-0.25288 0.0281 0.504"
			rpy="-1.5708 0 0" />
		<parent
			link="base_link" />
		<child
			link="shoulder_1_link" />
		<axis
			xyz="0 0 -1" />
		<limit
			effort="30"
			velocity="3"
			lower="-1.5708"
			upper="1.5708" />
	</joint>
	<link
		name="upper_1_link">
		<inertial>
			<origin
				xyz="0.050894 0.0017192 0.011382"
				rpy="0 0 0" />
			<mass
				value="0.43163" />
			<inertia
				ixx="7.0522E-06"
				ixy="6.2391E-06"
				ixz="8.7356E-06"
				iyy="2.3641E-05"
				iyz="-3.2847E-06"
				izz="2.1145E-05" />
		</inertial>
		<visual>
			<origin
				xyz="0 0 0"
				rpy="0 0 0" />
			<geometry>
				<mesh
					filename="package://ardop_description_01/meshes/upper_1_link.STL" />
			</geometry>
			<material
				name="red">
				<color
					rgba="0.91 0.3 0.24 1" />
			</material>
		</visual>
		<collision>
			<origin
				xyz="0 0 0"
				rpy="0 0 0" />
			<geometry>
				<mesh
					filename="package://ardop_description_01/meshes/upper_1_link.STL" />
			</geometry>
		</collision>
	</link>
	<joint
		name="upper_1_joint"
		type="revolute">
		<origin
			xyz="-0.075963 -0.0044026 -0.027024"
			rpy="-1.5708 0 1.5708" />
		<parent
			link="shoulder_1_link" />
		<child
			link="upper_1_link" />
		<axis
			xyz="0 0 -1" />
		<limit
			effort="30"
			velocity="3"
			lower="-1.5708"
			upper="1.5708" />
	</joint>
	<link
		name="upper_2_link">
		<inertial>
			<origin
				xyz="-2.8593E-07 -0.00051458 0.015855"
				rpy="0 0 0" />
			<mass
				value="0.36903" />
			<inertia
				ixx="2.2338E-06"
				ixy="-4.4296E-12"
				ixz="-6.4887E-12"
				iyy="1.8341E-06"
				iyz="-8.205E-07"
				izz="3.9972E-07" />
		</inertial>
		<visual>
			<origin
				xyz="0 0 0"
				rpy="0 0 0" />
			<geometry>
				<mesh
					filename="package://ardop_description_01/meshes/upper_2_link.STL" />
			</geometry>
			<material
				name="red">
				<color
					rgba="0.91 0.3 0.24 1" />
			</material>
		</visual>
		<collision>
			<origin
				xyz="0 0 0"
				rpy="0 0 0" />
			<geometry>
				<mesh
					filename="package://ardop_description_01/meshes/upper_2_link.STL" />
			</geometry>
		</collision>
	</link>
	<joint
		name="upper_2_joint"
		type="revolute">
		<origin
			xyz="0.10399 0.0036638 0"
			rpy="-1.5708 0 -1.5365" />
		<parent
			link="upper_1_link" />
		<child
			link="upper_2_link" />
		<axis
			xyz="0 0 -1" />
		<limit
			effort="30"
			velocity="3"
			lower="-1.5708"
			upper="1.5708" />
	</joint>
	<link
		name="lower_1_link">
		<inertial>
			<origin
				xyz="0.064437 2.5668E-07 -0.030026"
				rpy="0 0 0" />
			<mass
				value="0.52388" />
			<inertia
				ixx="3.3368E-06"
				ixy="-2.2132E-10"
				ixz="1.762E-05"
				iyy="0.00014342"
				iyz="-4.855E-11"
				izz="0.00014008" />
		</inertial>
		<visual>
			<origin
				xyz="0 0 0"
				rpy="0 0 0" />
			<geometry>
				<mesh
					filename="package://ardop_description_01/meshes/lower_1_link.STL" />
			</geometry>
			<material
				name="red">
				<color
					rgba="0.91 0.3 0.24 1" />
			</material>
		</visual>
		<collision>
			<origin
				xyz="0 0 0"
				rpy="0 0 0" />
			<geometry>
				<mesh
					filename="package://ardop_description_01/meshes/lower_1_link.STL" />
			</geometry>
		</collision>
	</link>
	<joint
		name="lower_1_joint"
		type="revolute">
		<origin
			xyz="0 0.025054 0.070279"
			rpy="-1.5708 -1.5365 -9.9855E-15" />
		<parent
			link="upper_2_link" />
		<child
			link="lower_1_link" />
		<axis
			xyz="0 0 1" />
		<limit
			effort="30"
			velocity="3"
			lower="-1.5708"
			upper="1.5708" />
	</joint>
	<link
		name="lower_2_link">
		<inertial>
			<origin
				xyz="0.0035775 0.0012219 0.05944"
				rpy="0 0 0" />
			<mass
				value="0.6" />
			<inertia
				ixx="0.00092995"
				ixy="-8.1424E-06"
				ixz="-0.00014702"
				iyy="0.00096142"
				iyz="-5.2609E-05"
				izz="3.7457E-05" />
		</inertial>
		<visual>
			<origin
				xyz="0 0 0"
				rpy="0 0 0" />
			<geometry>
				<mesh
					filename="package://ardop_description_01/meshes/lower_2_link.STL" />
			</geometry>
			<material
				name="red">
				<color
					rgba="0.91 0.3 0.24 1" />
			</material>
		</visual>
		<collision>
			<origin
				xyz="0 0 0"
				rpy="0 0 0" />
			<geometry>
				<mesh
					filename="package://ardop_description_01/meshes/lower_2_link.STL" />
			</geometry>
		</collision>
	</link>
	<joint
		name="lower_2_joint"
		type="revolute">
		<origin
			xyz="0.12948 0 -0.030211"
			rpy="0 1.5708 0" />
		<parent
			link="lower_1_link" />
		<child
			link="lower_2_link" />
		<axis
			xyz="0 0 -1" />
		<limit
			effort="30"
			velocity="3"
			lower="-1.5708"
			upper="1.5708" />
	</joint>
	<link
		name="end_effector_link">
		<inertial>
			<origin
				xyz="-0.018746 0.045341 -0.017775"
				rpy="0 0 0" />
			<mass
				value="0.12" />
			<inertia
				ixx="1.3948E-06"
				ixy="4.9399E-07"
				ixz="-2.0212E-07"
				iyy="4.0427E-07"
				iyz="4.8886E-07"
				izz="1.399E-06" />
		</inertial>
		<visual>
			<origin
				xyz="0 0 0"
				rpy="0 0 0" />
			<geometry>
				<mesh
					filename="package://ardop_description_01/meshes/end_effector_link.STL" />
			</geometry>
			<material
				name="blue">
				<color
					rgba="0.2 0.6 0.86 1" />
			</material>
		</visual>
		<collision>
			<origin
				xyz="0 0 0"
				rpy="0 0 0" />
			<geometry>
				<mesh
					filename="package://ardop_description_01/meshes/end_effector_link.STL" />
			</geometry>
		</collision>
	</link>
	<joint
		name="end_effector_joint"
		type="revolute">
		<origin
			xyz="-0.011541 -0.020552 0.12357"
			rpy="1.5708 0 0" />
		<parent
			link="lower_2_link" />
		<child
			link="end_effector_link" />
		<axis
			xyz="0 0 1" />
		<limit
			effort="30"
			velocity="3"
			lower="-1.5708"
			upper="1.5708" />
	</joint>
</robot>
